Workbook

Sheet รวมทุกแผนก
A1: แผนก | B1: รหัส SDS | C1: ชื่อผลิตภัณฑ์/สารเคมี | D1: Trade Name | E1: ปริมาณสูงสุดที่มี | F1: พื้นที่/หน่วยงานที่จัดเก็บ | G1: สารออกซิไดซ์ | H1: สารไวไฟ | I1: วัตถุระเบิด | J1: วัตถุมีพิษ | K1: สารกัดกร่อน | L1: แก๊ส | M1: อันตรายต่อสุขภาพ | N1: อันตรายต่อสิ่งแวดล้อม | O1: วัตถุระคายเคือง | P1: ประเภทอื่น ๆ | Q1: สวมถุงมือ | R1: สวมหน้ากาก | S1: สวมแว่นตา | T1: สวมเสื้อกันสารเคมี | U1: รองเท้าบู๊ท | V1: ต้องประกาศ Code 1 | W1: สารเคมีไวไฟในแผนก
A2: ศูนย์ทางเดินปัสสาวะ | B2: SDS-00001 | C2: =INDEX(รายการสาร!$B:$B,MATCH($B2,รายการสาร!$A:$A,0)) -> น้ำยา 3 Enzyme | D2: =INDEX(รายการสาร!$C:$C,MATCH($B2,รายการสาร!$A:$A,0)) -> 3 Enzyme | E2: 2X5L | F2: ตู้ไม้ | M2: ✓ | N2: ✓ | Q2: ✓ | S2: ✓ | V2: ✓
A3: ศูนย์ทางเดินปัสสาวะ | B3: SDS-00002 | C3: =INDEX(รายการสาร!$B:$B,MATCH($B3,รายการสาร!$A:$A,0)) -> น้ำยาแช่เครื่องมือ Cidex | D3: =INDEX(รายการสาร!$C:$C,MATCH($B3,รายการสาร!$A:$A,0)) -> Cidex | E3: 2X5L | F3: ตู้ไม้ | M3: ✓ | O3: ✓ | Q3: ✓ | S3: ✓ | V3: ✓
A4: ศูนย์ทางเดินปัสสาวะ | B4: SDS-00003 | C4: =INDEX(รายการสาร!$B:$B,MATCH($B4,รายการสาร!$A:$A,0)) -> คิมแคร์สบู่เหลวล้างมือ | D4: =INDEX(รายการสาร!$C:$C,MATCH($B4,รายการสาร!$A:$A,0)) -> Kimcare | E4: 500 ml | F4: ห้องตรวจ | O4: ✓
A5: ศูนย์ทางเดินปัสสาวะ | B5: SDS-00004 | C5: =INDEX(รายการสาร!$B:$B,MATCH($B5,รายการสาร!$A:$A,0)) -> น้ำยาล้างจาน | D5: =INDEX(รายการสาร!$C:$C,MATCH($B5,รายการสาร!$A:$A,0)) -> ไลปอนเอฟ หรือ มาวิน หรือ ซันไลต์ | E5: 1X120 ml | F5: ตู้ไม้ | O5: ✓
A6: ศูนย์ทางเดินปัสสาวะ | B6: SDS-00005 | C6: =INDEX(รายการสาร!$B:$B,MATCH($B6,รายการสาร!$A:$A,0)) -> Avagard Foaming Instant Hand Antiseptic | D6: =INDEX(รายการสาร!$C:$C,MATCH($B6,รายการสาร!$A:$A,0)) -> Avagard Foaming Instant Hand Antiseptic | E6: 1X500ml | F6: ติดผนัง | H6: ✓ | O6: ✓ | W6: ✓
A7: ศูนย์ทางเดินปัสสาวะ | B7: SDS-00006 | C7: =INDEX(รายการสาร!$B:$B,MATCH($B7,รายการสาร!$A:$A,0)) -> 70% alcohol | D7: =INDEX(รายการสาร!$C:$C,MATCH($B7,รายการสาร!$A:$A,0)) -> Preservative solution 70% | E7: 6X 60 ml | F7: ตู้เก็บน้ำยา | H7: ✓ | W7: ✓
A8: คลินิกหู คอ จมูก | B8: SDS-00007 | C8: =INDEX(รายการสาร!$B:$B,MATCH($B8,รายการสาร!$A:$A,0)) -> Ammonia | D8: =INDEX(รายการสาร!$C:$C,MATCH($B8,รายการสาร!$A:$A,0)) -> Ammonia | E8: 3X30 ml | F8: ตู้เก็บสารเคมี | J8: ✓ | K8: ✓ | M8: ✓ | Q8: ✓ | R8: ✓
A9: คลินิกหู คอ จมูก | B9: SDS-00006 | C9: =INDEX(รายการสาร!$B:$B,MATCH($B9,รายการสาร!$A:$A,0)) -> 70% alcohol | D9: =INDEX(รายการสาร!$C:$C,MATCH($B9,รายการสาร!$A:$A,0)) -> Preservative solution 70% | E9: 3x60 ml | F9: ตู้เก็บสารเคมี | H9: ✓ | W9: ✓
A10: คลินิกหู คอ จมูก | B10: SDS-00004 | C10: =INDEX(รายการสาร!$B:$B,MATCH($B10,รายการสาร!$A:$A,0)) -> น้ำยาล้างจาน | D10: =INDEX(รายการสาร!$C:$C,MATCH($B10,รายการสาร!$A:$A,0)) -> ไลปอนเอฟ หรือ มาวิน หรือ ซันไลต์ | E10: 500 ml | F10: ตู้เก็บสารเคมี | O10: ✓
A11: คลินิกหู คอ จมูก | B11: SDS-00008 | C11: =INDEX(รายการสาร!$B:$B,MATCH($B11,รายการสาร!$A:$A,0)) -> Virusolve | D11: =INDEX(รายการสาร!$C:$C,MATCH($B11,รายการสาร!$A:$A,0)) -> Virusolve | E11: 3X5000 ml | F11: ตู้เก็บสารเคมี | M11: ✓ | Q11: ✓ | R11: ✓ | S11: ✓ | V11: ✓
A12: คลินิกหู คอ จมูก | B12: SDS-00009 | C12: =INDEX(รายการสาร!$B:$B,MATCH($B12,รายการสาร!$A:$A,0)) -> น้ำยาล้างเล็บ(LAPPA) | D12: =INDEX(รายการสาร!$C:$C,MATCH($B12,รายการสาร!$A:$A,0)) -> Polish Remover | E12: 1x400 ml | F12: ตู้เก็บสารเคมี | H12: ✓ | M12: ✓ | O12: ✓ | Q12: ✓ | W12: ✓
A13: คลินิกหู คอ จมูก | B13: SDS-00010 | C13: =INDEX(รายการสาร!$B:$B,MATCH($B13,รายการสาร!$A:$A,0)) -> Gel ล้างมือติดผนัง | D13: =INDEX(รายการสาร!$C:$C,MATCH($B13,รายการสาร!$A:$A,0)) -> Purell | E13: 1000 ml | F13: ผนัง | H13: ✓ | W13: ✓
A14: คลินิกหู คอ จมูก | B14: SDS-00011 | C14: =INDEX(รายการสาร!$B:$B,MATCH($B14,รายการสาร!$A:$A,0)) -> Alcohol Gel | D14: =INDEX(รายการสาร!$C:$C,MATCH($B14,รายการสาร!$A:$A,0)) -> Clear Hand Gel | E14: 6x120 mll | F14: ตู้เก็บสารเคมี | H14: ✓ | W14: ✓
A15: คลินิกหู คอ จมูก | B15: SDS-00012 | C15: =INDEX(รายการสาร!$B:$B,MATCH($B15,รายการสาร!$A:$A,0)) -> Betadine | D15: =INDEX(รายการสาร!$C:$C,MATCH($B15,รายการสาร!$A:$A,0)) -> Betadine | E15: 3x30 mll | F15: ตู้เก็บสารเคมี | O15: ✓ | Q15: ✓
A16: คลินิกหู คอ จมูก | B16: SDS-00013 | C16: =INDEX(รายการสาร!$B:$B,MATCH($B16,รายการสาร!$A:$A,0)) -> CHLORHEXIDINE SCRUB 4% | D16: =INDEX(รายการสาร!$C:$C,MATCH($B16,รายการสาร!$A:$A,0)) -> Hexene | E16: 3x100 ml | F16: ตู้เก็บสารเคมี | H16: ✓ | M16: ✓ | Q16: ✓ | W16: ✓
A17: คลินิกหู คอ จมูก | B17: SDS-00014 | C17: =INDEX(รายการสาร!$B:$B,MATCH($B17,รายการสาร!$A:$A,0)) -> 6% Hydrogen peroxide | D17: =INDEX(รายการสาร!$C:$C,MATCH($B17,รายการสาร!$A:$A,0)) -> 6% Hydrogen peroxide | E17: 3X60 ml | F17: ตู้เก็บสารเคมี
A18: คลินิกหู คอ จมูก | B18: SDS-00015 | C18: =INDEX(รายการสาร!$B:$B,MATCH($B18,รายการสาร!$A:$A,0)) -> 95% alcohol | D18: =INDEX(รายการสาร!$C:$C,MATCH($B18,รายการสาร!$A:$A,0)) -> 95% alcohol | E18: 4X450 ml | F18: ตู้เก็บสารเคมี | H18: ✓ | W18: ✓
A19: คลินิกหู คอ จมูก | B19: SDS-00016 | C19: =INDEX(รายการสาร!$B:$B,MATCH($B19,รายการสาร!$A:$A,0)) -> 0.5 % chlorhexidine in water (Hibitane 1:10) | D19: =INDEX(รายการสาร!$C:$C,MATCH($B19,รายการสาร!$A:$A,0)) -> 0.5 % chlorhexidine in water (Hibitane 1:10) | E19: 3 x 120 ml | F19: ตู้เก็บสารเคมี | O19: ✓ | Q19: ✓
A20: คลินิกหู คอ จมูก | B20: SDS-00003 | C20: =INDEX(รายการสาร!$B:$B,MATCH($B20,รายการสาร!$A:$A,0)) -> คิมแคร์สบู่เหลวล้างมือ | D20: =INDEX(รายการสาร!$C:$C,MATCH($B20,รายการสาร!$A:$A,0)) -> Kimcare | E20: 500 ml | F20: ห้องตรวจ | O20: ✓
A21: คลินิกหู คอ จมูก | B21: SDS-00017 | C21: =INDEX(รายการสาร!$B:$B,MATCH($B21,รายการสาร!$A:$A,0)) -> Alcohol Pad | D21: =INDEX(รายการสาร!$C:$C,MATCH($B21,รายการสาร!$A:$A,0)) -> Neoplast | E21: 4 กล่อง | F21: ตู้เก็บสารเคมี | H21: ✓ | W21: ✓
A22: แม่บ้าน | B22: SDS-00018 | C22: =INDEX(รายการสาร!$B:$B,MATCH($B22,รายการสาร!$A:$A,0)) -> 2-butoxyethanol | D22: =INDEX(รายการสาร!$C:$C,MATCH($B22,รายการสาร!$A:$A,0)) -> Glance HC (กล๊านซ์ เอชซี) | E22: 6 x 5 l | F22: คลังแม่บ้าน | K22: ✓ | Q22: ✓ | S22: ✓ | U22: ✓ | V22: ✓
A23: แม่บ้าน | B23: SDS-00019 | C23: =INDEX(รายการสาร!$B:$B,MATCH($B23,รายการสาร!$A:$A,0)) -> Alcohol ethoxylates | D23: =INDEX(รายการสาร!$C:$C,MATCH($B23,รายการสาร!$A:$A,0)) -> Stride Floral HC (สไตร์ด ฟลอรัล เอชซี) | E23: 2.5 l | F23: คลังแม่บ้าน | K23: ✓ | Q23: ✓ | S23: ✓ | V23: ✓
A24: แม่บ้าน | B24: SDS-00020 | C24: =INDEX(รายการสาร!$B:$B,MATCH($B24,รายการสาร!$A:$A,0)) -> Premia (พรีเมียร์) | D24: =INDEX(รายการสาร!$C:$C,MATCH($B24,รายการสาร!$A:$A,0)) -> Premia (พรีเมียร์) | E24: 8X19L | F24: คลังแม่บ้าน | O24: ✓ | Q24: ✓ | V24: ✓
A25: แม่บ้าน | B25: SDS-00021 | C25: =INDEX(รายการสาร!$B:$B,MATCH($B25,รายการสาร!$A:$A,0)) -> Butyl Cellosolve, Sodium Xylene Sulfonate | D25: =INDEX(รายการสาร!$C:$C,MATCH($B25,รายการสาร!$A:$A,0)) -> J-Shop 600 (เจ-ชอพ 600 | E25: 5L | F25: คลังแม่บ้าน | K25: ✓ | Q25: ✓ | S25: ✓ | V25: ✓
A26: แม่บ้าน | B26: SDS-00022 | C26: =INDEX(รายการสาร!$B:$B,MATCH($B26,รายการสาร!$A:$A,0)) -> Distillates (petroleum), hydrotreated light | D26: =INDEX(รายการสาร!$C:$C,MATCH($B26,รายการสาร!$A:$A,0)) -> Conq-R-Dust (คองเคอร์ดัสท์) | E26: 4L | F26: คลังแม่บ้าน | H26: ✓ | M26: ✓ | N26: ✓ | O26: ✓ | Q26: ✓ | V26: ✓ | W26: ✓
A27: แม่บ้าน | B27: SDS-00023 | C27: =INDEX(รายการสาร!$B:$B,MATCH($B27,รายการสาร!$A:$A,0)) -> Distillates (petroleum), hydrotreated light | D27: =INDEX(รายการสาร!$C:$C,MATCH($B27,รายการสาร!$A:$A,0)) -> Suma Inox (ซูม่าไอน็อก) | E27: 5L | F27: คลังแม่บ้าน | M27: ✓ | N27: ✓ | O27: ✓ | Q27: ✓ | S27: ✓ | V27: ✓ | W27: ✓
A28: แม่บ้าน | B28: SDS-00024 | C28: =INDEX(รายการสาร!$B:$B,MATCH($B28,รายการสาร!$A:$A,0)) -> Forward DC ฟอร์เวิด ดีซี | D28: =INDEX(รายการสาร!$C:$C,MATCH($B28,รายการสาร!$A:$A,0)) -> Forward DC ฟอร์เวิด ดีซี | E28: 6 x 20 l | F28: คลังแม่บ้าน | K28: ✓ | Q28: ✓ | S28: ✓ | V28: ✓
A29: แม่บ้าน | B29: SDS-00025 | C29: =INDEX(รายการสาร!$B:$B,MATCH($B29,รายการสาร!$A:$A,0)) -> General Purpose Spotter | D29: =INDEX(รายการสาร!$C:$C,MATCH($B29,รายการสาร!$A:$A,0)) -> General Purpose Spotter | E29: 4X5L | F29: คลังแม่บ้าน | O29: ✓ | Q29: ✓ | S29: ✓ | V29: ✓
A30: แม่บ้าน | B30: SDS-00026 | C30: =INDEX(รายการสาร!$B:$B,MATCH($B30,รายการสาร!$A:$A,0)) -> Monoethanolamine | D30: =INDEX(รายการสาร!$C:$C,MATCH($B30,รายการสาร!$A:$A,0)) -> GP Forward SC Cleaner (จีพี ฟอร์เวิร์ด เอสซี คลีนเซอร์) | E30: 2.5L | F30: คลังแม่บ้าน | M30: ✓ | O30: ✓ | Q30: ✓ | V30: ✓
A31: แม่บ้าน | B31: SDS-00027 | C31: =INDEX(รายการสาร!$B:$B,MATCH($B31,รายการสาร!$A:$A,0)) -> N-Alkyl Dimethylbenzene Ammonium chloride, Tetrasodium Salt of EDTA, Didecyl Dimethyl Ammonium chloride | D31: =INDEX(รายการสาร!$C:$C,MATCH($B31,รายการสาร!$A:$A,0)) -> Virex II 256 (ไวเร็กซ์ II 256) | E31: 2.5L | F31: คลังแม่บ้าน | K31: ✓ | N31: ✓ | Q31: ✓ | R31: ✓ | S31: ✓ | T31: ✓ | V31: ✓
A32: แม่บ้าน | B32: SDS-00028 | C32: =INDEX(รายการสาร!$B:$B,MATCH($B32,รายการสาร!$A:$A,0)) -> Jonseal 220 จอห์นซีล 220 | D32: =INDEX(รายการสาร!$C:$C,MATCH($B32,รายการสาร!$A:$A,0)) -> Jonseal 220 จอห์นซีล 220 | E32: 5L | F32: คลังแม่บ้าน | O32: ✓ | Q32: ✓ | V32: ✓
A33: แม่บ้าน | B33: SDS-00029 | C33: =INDEX(รายการสาร!$B:$B,MATCH($B33,รายการสาร!$A:$A,0)) -> Sodium ABS, Sodium silicate, Sodium carbonate | D33: =INDEX(รายการสาร!$C:$C,MATCH($B33,รายการสาร!$A:$A,0)) -> Tempo (เทมโป้) | E33: 25 kg | F33: คลังแม่บ้าน | K33: ✓ | Q33: ✓ | S33: ✓ | V33: ✓
A34: แม่บ้าน | B34: SDS-00030 | C34: =INDEX(รายการสาร!$B:$B,MATCH($B34,รายการสาร!$A:$A,0)) -> Sodium Hydroxide, Monoethanolamine | D34: =INDEX(รายการสาร!$C:$C,MATCH($B34,รายการสาร!$A:$A,0)) -> Step Off (สะเต็ปออฟ) | E34: 5L | F34: คลังแม่บ้าน | K34: ✓ | Q34: ✓ | R34: ✓ | S34: ✓ | V34: ✓
A35: แม่บ้าน | B35: SDS-00031 | C35: =INDEX(รายการสาร!$B:$B,MATCH($B35,รายการสาร!$A:$A,0)) -> Taski Omnispray ออมนิสเปรย์ | D35: =INDEX(รายการสาร!$C:$C,MATCH($B35,รายการสาร!$A:$A,0)) -> Taski Omnispray ออมนิสเปรย์ | E35: 4X5L | F35: คลังแม่บ้าน | O35: ✓ | Q35: ✓ | V35: ✓
A36: แม่บ้าน | B36: SDS-00032 | C36: =INDEX(รายการสาร!$B:$B,MATCH($B36,รายการสาร!$A:$A,0)) -> Taski Omnistrip ออมนิสตริป | D36: =INDEX(รายการสาร!$C:$C,MATCH($B36,รายการสาร!$A:$A,0)) -> Taski Omnistrip ออมนิสตริป | E36: 4X5L | F36: คลังแม่บ้าน | O36: ✓ | Q36: ✓ | V36: ✓
A37: แม่บ้าน | B37: SDS-00033 | C37: =INDEX(รายการสาร!$B:$B,MATCH($B37,รายการสาร!$A:$A,0)) -> เอเมอเริล มัลติ-เซอร์เฟส ครีม คลีนเซอร์ | D37: =INDEX(รายการสาร!$C:$C,MATCH($B37,รายการสาร!$A:$A,0)) -> Emerel เอเมอเริล | E37: 12 ขวด | F37: คลังแม่บ้าน | K37: ✓ | Q37: ✓ | S37: ✓
A38: แม่บ้าน | B38: SDS-00034 | C38: =INDEX(รายการสาร!$B:$B,MATCH($B38,รายการสาร!$A:$A,0)) -> Taski Metal Polish ทัสกิ เมทอล โพลิส | D38: =INDEX(รายการสาร!$C:$C,MATCH($B38,รายการสาร!$A:$A,0)) -> Taski Metal Polish ทัสกิ เมทอล โพลิส | E38: 20 X 190g | F38: คลังแม่บ้าน | Q38: ✓ | S38: ✓ | V38: ✓
A39: แม่บ้าน | B39: SDS-00035 | C39: =INDEX(รายการสาร!$B:$B,MATCH($B39,รายการสาร!$A:$A,0)) -> แคล็กซ์ ผงซักฟอกด้วยเครื่อง | D39: =INDEX(รายการสาร!$C:$C,MATCH($B39,รายการสาร!$A:$A,0)) -> CLAX powder แคล็กซ์พาวเดอร์ | F39: คลังแม่บ้าน | O39: ✓ | Q39: ✓ | R39: ✓
A40: แม่บ้าน | B40: SDS-00036 | C40: =INDEX(รายการสาร!$B:$B,MATCH($B40,รายการสาร!$A:$A,0)) -> HDF cleaner | D40: =INDEX(รายการสาร!$C:$C,MATCH($B40,รายการสาร!$A:$A,0)) -> HDF cleaner | F40: คลังแม่บ้าน | K40: ✓ | Q40: ✓ | S40: ✓ | V40: ✓
...

Sheet รายการสาร
A1: รหัส SDS | B1: ชื่อผลิตภัณฑ์/สารเคมี | C1: Trade Name
A2: SDS-00001 | B2: น้ำยา 3 Enzyme | C2: 3 Enzyme
A3: SDS-00002 | B3: น้ำยาแช่เครื่องมือ Cidex | C3: Cidex
A4: SDS-00003 | B4: คิมแคร์สบู่เหลวล้างมือ | C4: Kimcare
A5: SDS-00004 | B5: น้ำยาล้างจาน | C5: ไลปอนเอฟ หรือ มาวิน หรือ ซันไลต์
A6: SDS-00005 | B6: Avagard Foaming Instant Hand Antiseptic | C6: Avagard Foaming Instant Hand Antiseptic
A7: SDS-00006 | B7: 70% alcohol | C7: Preservative solution 70%
A8: SDS-00007 | B8: Ammonia | C8: Ammonia
A9: SDS-00008 | B9: Virusolve | C9: Virusolve
A10: SDS-00009 | B10: น้ำยาล้างเล็บ(LAPPA) | C10: Polish Remover
A11: SDS-00010 | B11: Gel ล้างมือติดผนัง | C11: Purell
A12: SDS-00011 | B12: Alcohol Gel | C12: Clear Hand Gel
... A38: SDS-00037 | B38: Crew Lime and Scale Remover | C38: Crew Lime and Scale Remover
A39: SDS-00038 | B39: Glade Spa Fresh
A40: SDS-00039 | B40: ไลปอนเอฟและ Marvin น้ำยาล้างจาน | C40: ไลปอนเอฟ หรือ มาวิน หรือ ซันไลต์
A41: SDS-00040 | B41: น้ำมันหอมละเหย | C41: ยูคาลิปตัส
A42: SDS-00041 | B42: VirKon disinfectant | C42: VirKon disinfectant
A43: SDS-00042 | B43: Gel ล้างมือติดผนัง | C43: Purell (Hand Sanitizer)
A44: SDS-00043 | B44: Suma SaturnD4.9( ซูม่าแซทเทิร์นดี4.9) | C44: Suma Saturn D4.9 ( ซูม่าแซทเทิร์นดี4.9)
A45: SDS-00044 | B45: Taski Jontec ESD(ทัสกิ จอนเทค อีเอสดี ) | C45: Taski Jontec ESD(ทัสกิ จอนเทค อีเอสดี )
A46: SDS-00045 | B46: Oxivir TB (Benzyl alcohol) | C46: Oxivir TB
A47: SDS-00046 | B47: Trisodium nitrilotriacetate, Sodium Hydroxide | C47: Suma Special
A48: SDS-00047 | B48: Alkyl alcohol alkoxylate | C48: Suma Quick Dri
A49: SDS-00048 | B49: Sodium alkylbenzene sulphonate | C49: Suma Star
A50: SDS-00049 | B50: Dodeccyl Benzene Sulfonic Acid ,Sodium Xylene Sulfonate , Ethoxylated alcohol | C50: Suma Stopp Slip
A51: SDS-00050 | B51: Sodium Metasilicate ,Sodium Hydroxide ,Anionics | C51: Suma Break Up HD
... A84: SDS-00083 | B84: Frekaderm | C84: Frekaderm
A85: SDS-00084 | B85: 30 % citric acid
A86: SDS-00085 | B86: Sodium hypochlorite | C86: 5% chlorox
A87: SDS-00086 | B87: citrosteril
A88: SDS-00087 | B88: peracitic acid
A89: SDS-00088 | B89: Chlorhexidine | C89: Q-Bac 2A
A90: SDS-00089 | B90: 2% chlohexidine in 70% alcohol | C90: Prepskin-C
A91: SDS-00090 | B91: Chlorhexidine solution (2%) | C91: Chlorhexidine solution (2%)
A92: SDS-00091 | B92: EDTA 17% solution : aionsyme plus | C92: EDTA 17% solution : aionsyme plus
A93: SDS-00092 | B93: Ethy alcohol 70% | C93: Preservative solution 70%
A94: SDS-00093 | B94: 95 % Alcohol | C94: 95 % Alcohol
A95: SDS-00094 | B95: Mybacin | C95: Mybacin
A96: SDS-00095 | B96: Hydrogen peroxide | C96: Hydrogen peroxide
A97: SDS-00096 | B97: Chlorhexidine scrub (4%) | C97: Hexene
...

Sheet สรุปการประมวลผล
A1: รายการ | B1: ค่า
A2: ไฟล์ต้นทาง | B2: ตารางรายการสารเคมีอัพเดท -23122025.xlsx
A3: ไฟล์ปลายทาง | B3: ตารางรายการสารเคมีรวมทุกแผนก.xlsx
A4: จำนวนชีตแผนกที่ใช้ | B4: 64
A5: จำนวนรายการรวมทุกแผนก | B5: 661
A6: จำนวนรายการสารไม่ซ้ำ | B6: 337
A7: จำนวนแถวข้อมูลไม่ตรงกัน | B7: 64
A9: ชีตที่นำเข้าข้อมูล | B9: แผนก | C9: จำนวนรายการ
A10: 1.URO | B10: ศูนย์ทางเดินปัสสาวะ | C10: 6
A11: 2.ENT | B11: คลินิกหู คอ จมูก | C11: 14
A12: 3.แม่บ้าน | B12: แม่บ้าน | C12: 29
A13: 4.ฟู้ดเฮ้า | B13: ฟู้ดเฮ้าส์ | C13: 13
A14: 5.CSSD | B14: CSSD | C14: 10
A15: 6.w 7 | B15: คลินิกผู้ป่วยใน w7 | C15: 12
A16: 7.w8 | B16: คลินิกผู้ป่วยในหัวใจ w8 | C16: 14
A17: 8.w9 | B17: คลินิกผู้ป่วยในw9 | C17: 10
A18: 9.W10 | B18: ward 10 | C18: 13
A19: 10.W11 | B19: แผนกผู้ป่วยในศูนย์สุขภาพเด็กw11 | C19: 6
A20: 11.W12 | B20: แผนกผู้ป่วยในศูนย์สุขภาพเด็กw12 | C20: 7
A21: 12.w15 | B21: ward 15 | C21: 13
... A73: 63. CN | B73: คัดกรองผู้ป่วย | C73: 6
